<mujoco model="solo">
    <compiler angle="radian"/>

    <option timestep="0.001"/>

    <size njmax="500" nconmax="100"/>

    <default>
        <default class="solo12">
            <default class="contact">
                <geom condim="6" friction="0.6 0.005 0.0001" solref="0.015 1" solimp="0.99 0.99 0.001" priority="1"/>
            </default>
        </default>
    </default>

    <asset>
        <mesh name="solo_12_base" file="solo12_stl/solo_12_base.stl"/>
        <mesh name="solo12_hip_fe_fl" file="solo12_stl/solo12_hip_fe_fl.stl"/>
        <mesh name="solo_upper_leg_left_side" file="solo12_stl/solo_upper_leg_left_side.stl"/>
        <mesh name="solo_lower_leg_left_side" file="solo12_stl/solo_lower_leg_left_side.stl"/>
        <mesh name="solo_foot" file="solo12_stl/solo_foot.stl"/>
        <mesh name="solo12_hip_fe_fr" file="solo12_stl/solo12_hip_fe_fr.stl"/>
        <mesh name="solo_upper_leg_right_side" file="solo12_stl/solo_upper_leg_right_side.stl"/>
        <mesh name="solo_lower_leg_right_side" file="solo12_stl/solo_lower_leg_right_side.stl"/>
        <mesh name="solo12_hip_fe_hl" file="solo12_stl/solo12_hip_fe_hl.stl"/>
        <mesh name="solo12_hip_fe_hr" file="solo12_stl/solo12_hip_fe_hr.stl"/>
    </asset>
    <worldbody>
        <light name="top" pos="0 0 1.5"/>
        <geom name="floor" type="plane" size="5 5 .1" condim="6" friction="0.6 0.005 0.0001" solref="0.015 1" solimp="0.99 0.99 0.001"/>
        <body name="solo12" pos="0 0 .5" childclass="solo12">
            <joint armature="0" damping="0" limited="false" name="base" pos="0 0 0" stiffness="0" type="free"/>
            <inertial pos="0 0 0" mass="1.16115091" fullinertia="0.00578574 0.01938108 0.02476124 0.0 0.0 0.0" />
            <geom type="mesh" rgba="0.8 0.8 0.8 1" mesh="solo_12_base"/>
            <body name="FL_SHOULDER" pos="0.1946 0.0875 0">
                <inertial pos="-0.078707 0.01 0" quat="0.529086 0.529086 0.469114 0.469114" mass="0.148538" diaginertia="0.000417563 0.00041107 2.46069e-05"/>
                <joint name="FL_HAA" pos="0 0 0" axis="1 0 0" limited="true" range="-10 10"/>
                <geom pos="0.0195 0 0" type="mesh" rgba="0.8 0.8 0.8 1" mesh="solo12_hip_fe_fl"/>
                <body name="FL_UPPER_LEG" pos="0 0.014 0">
                    <inertial pos="1.377e-05 0.0193585 -0.078707" quat="0.705834 0.0424071 -0.0424071 0.705834" mass="0.148538" diaginertia="0.000417563 0.00041107 2.46069e-05"/>
                    <joint name="FL_HFE" pos="0 0 0" axis="0 1 0" limited="true" range="-10 10"/>
                    <geom type="mesh" rgba="0.8 0.8 0.8 1" mesh="solo_upper_leg_left_side"/>
                    <body name="FL_LOWER_LEG" pos="0 0.03745 -0.16">
                        <inertial pos="0 0.00789921 -0.102249" quat="0.707067 0.00747737 -0.00747737 0.707067" mass="0.0376361" diaginertia="0.000149205 0.000148819 2.62453e-06"/>
                        <joint name="FL_KFE" pos="0 0 0" axis="0 1 0" limited="true" range="-10 10"/>
                        <geom type="mesh" rgba="0.8 0.8 0.8 1" mesh="solo_lower_leg_left_side"/>
                        <geom pos="0 0.008 -0.16" type="mesh" rgba="0.8 0.8 0.8 1" mesh="solo_foot" class="contact"/>
                    </body>
                </body>
            </body>
            <body name="FR_SHOULDER" pos="0.1946 -0.0875 0">
                <inertial pos="-0.078707 -0.01 0" quat="0.469114 0.469114 0.529086 0.529086" mass="0.148538" diaginertia="0.000417563 0.00041107 2.46069e-05"/>
                <joint name="FR_HAA" pos="0 0 0" axis="1 0 0" limited="true" range="-10 10"/>
                <geom pos="0.0195 0 0" type="mesh" rgba="0.8 0.8 0.8 1" mesh="solo12_hip_fe_fr"/>
                <body name="FR_UPPER_LEG" pos="0 -0.014 0">
                    <inertial pos="-1.377e-05 -0.0193585 -0.078707" quat="0.705834 -0.0424071 0.0424071 0.705834" mass="0.148538" diaginertia="0.000417563 0.00041107 2.46069e-05"/>
                    <joint name="FR_HFE" pos="0 0 0" axis="0 1 0" limited="true" range="-10 10"/>
                    <geom type="mesh" rgba="0.8 0.8 0.8 1" mesh="solo_upper_leg_right_side"/>
                    <body name="FR_LOWER_LEG" pos="0 -0.03745 -0.16">
                        <inertial pos="0 0.00495053 -0.102249" quat="0.999484 -0.0321221 0 0" mass="0.0376361" diaginertia="0.000150245 0.000149742 3.5132e-06"/>
                        <joint name="FR_KFE" pos="0 0 0" axis="0 1 0" limited="true" range="-10 10"/>
                        <geom type="mesh" rgba="0.8 0.8 0.8 1" mesh="solo_lower_leg_right_side"/>
                        <geom pos="0 -0.008 -0.16" type="mesh" rgba="0.8 0.8 0.8 1" mesh="solo_foot" class="contact"/>
                    </body>
                </body>
            </body>
            <body name="HL_SHOULDER" pos="-0.1946 0.0875 0">
                <inertial pos="0.078707 0.01 0" quat="0.529086 0.529086 0.469114 0.469114" mass="0.148538" diaginertia="0.000417563 0.00041107 2.46069e-05"/>
                <joint name="HL_HAA" pos="0 0 0" axis="1 0 0" limited="true" range="-10 10"/>
                <geom pos="-0.0195 0 0" type="mesh" rgba="0.8 0.8 0.8 1" mesh="solo12_hip_fe_hl"/>
                <body name="HL_UPPER_LEG" pos="0 0.014 0">
                    <inertial pos="1.377e-05 0.0193585 -0.078707" quat="0.705834 0.0424071 -0.0424071 0.705834" mass="0.148538" diaginertia="0.000417563 0.00041107 2.46069e-05"/>
                    <joint name="HL_HFE" pos="0 0 0" axis="0 1 0" limited="true" range="-10 10"/>
                    <geom type="mesh" rgba="0.8 0.8 0.8 1" mesh="solo_upper_leg_left_side"/>
                    <body name="HL_LOWER_LEG" pos="0 0.03745 -0.16">
                        <inertial pos="0 0.00789921 -0.102249" quat="0.707067 0.00747737 -0.00747737 0.707067" mass="0.0376361" diaginertia="0.000149205 0.000148819 2.62453e-06"/>
                        <joint name="HL_KFE" pos="0 0 0" axis="0 1 0" limited="true" range="-10 10"/>
                        <geom type="mesh" rgba="0.8 0.8 0.8 1" mesh="solo_lower_leg_left_side"/>
                        <geom pos="0 0.008 -0.16" type="mesh" rgba="0.8 0.8 0.8 1" mesh="solo_foot" class="contact"/>
                    </body>
                </body>
            </body>
            <body name="HR_SHOULDER" pos="-0.1946 -0.0875 0">
                <inertial pos="0.078707 -0.01 0" quat="0.469114 0.469114 0.529086 0.529086" mass="0.148538" diaginertia="0.000417563 0.00041107 2.46069e-05"/>
                <joint name="HR_HAA" pos="0 0 0" axis="1 0 0" limited="true" range="-10 10"/>
                <geom pos="-0.0195 0 0" type="mesh" rgba="0.8 0.8 0.8 1" mesh="solo12_hip_fe_hr"/>
                <body name="HR_UPPER_LEG" pos="0 -0.014 0">
                    <inertial pos="-1.377e-05 -0.0193585 -0.078707" quat="0.705834 -0.0424071 0.0424071 0.705834" mass="0.148538" diaginertia="0.000417563 0.00041107 2.46069e-05"/>
                    <joint name="HR_HFE" pos="0 0 0" axis="0 1 0" limited="true" range="-10 10"/>
                    <geom type="mesh" rgba="0.8 0.8 0.8 1" mesh="solo_upper_leg_right_side"/>
                    <body name="HR_LOWER_LEG" pos="0 -0.03745 -0.16">
                        <inertial pos="0 0.00495053 -0.102249" quat="0.999484 -0.0321221 0 0" mass="0.0376361" diaginertia="0.000150245 0.000149742 3.5132e-06"/>
                        <joint name="HR_KFE" pos="0 0 0" axis="0 1 0" limited="true" range="-10 10"/>
                        <geom type="mesh" rgba="0.8 0.8 0.8 1" mesh="solo_lower_leg_right_side"/>
                        <geom pos="0 -0.008 -0.16" type="mesh" rgba="0.8 0.8 0.8 1" mesh="solo_foot" class="contact"/>
                    </body>
                </body>
            </body>
        </body>
    </worldbody>

    <actuator>
        <motor name="FL_HAA"       gear="1"  joint="FL_HAA"/>
        <motor name="FL_HFE"       gear="1"  joint="FL_HFE"/>
        <motor name="FL_KFE"       gear="1"  joint="FL_KFE"/>
        <motor name="FR_HAA"       gear="1"  joint="FR_HAA"/>
        <motor name="FR_HFE"       gear="1"  joint="FR_HFE"/>
        <motor name="FR_KFE"       gear="1"  joint="FR_KFE"/>
        <motor name="HL_HAA"       gear="1"  joint="HL_HAA"/>
        <motor name="HL_HFE"       gear="1"  joint="HL_HFE"/>
        <motor name="HL_KFE"       gear="1"  joint="HL_KFE"/>
        <motor name="HR_HAA"       gear="1"  joint="HR_HAA"/>
        <motor name="HR_HFE"       gear="1"  joint="HR_HFE"/>
        <motor name="HR_KFE"       gear="1"  joint="HR_KFE"/>
    </actuator>

    <contact>
        <!-- Prevent contact between the base and other body parts. -->
        <exclude body1='solo12' body2='FL_UPPER_LEG'/>
        <exclude body1='solo12' body2='FR_UPPER_LEG'/>
        <exclude body1='solo12' body2='HL_UPPER_LEG'/>
        <exclude body1='solo12' body2='HR_UPPER_LEG'/>
    </contact>
</mujoco>
